{"level":"ERROR","location":"[exception:108] fyers_logger","message":"onopen() missing 1 required positional argument: 'message'","timestamp":"2024-04-30 06:48:46,583+0000","service":"FyersDataSocket","exception":"Traceback (most recent call last):\n  File \"/usr/local/lib/python3.8/site-packages/fyers_apiv3/FyersWebsocket/data_ws.py\", line 1517, in on_open\n    self.OnOpen()\nTypeError: onopen() missing 1 required positional argument: 'message'","exception_name":"TypeError"}
{"level":"ERROR","location":"[exception:108] fyers_logger","message":"onopen() missing 1 required positional argument: 'message'","timestamp":"2024-04-30 06:49:10,947+0000","service":"FyersDataSocket","exception":"Traceback (most recent call last):\n  File \"/usr/local/lib/python3.8/site-packages/fyers_apiv3/FyersWebsocket/data_ws.py\", line 1517, in on_open\n    self.OnOpen()\nTypeError: onopen() missing 1 required positional argument: 'message'","exception_name":"TypeError"}
{"level":"ERROR","location":"[exception:108] fyers_logger","message":"onopen() missing 1 required positional argument: 'message'","timestamp":"2024-04-30 06:49:40,183+0000","service":"FyersDataSocket","exception":"Traceback (most recent call last):\n  File \"/usr/local/lib/python3.8/site-packages/fyers_apiv3/FyersWebsocket/data_ws.py\", line 1517, in on_open\n    self.OnOpen()\nTypeError: onopen() missing 1 required positional argument: 'message'","exception_name":"TypeError"}
{"level":"ERROR","location":"[exception:108] fyers_logger","message":"onopen() missing 1 required positional argument: 'message'","timestamp":"2024-04-30 06:50:14,169+0000","service":"FyersDataSocket","exception":"Traceback (most recent call last):\n  File \"/usr/local/lib/python3.8/site-packages/fyers_apiv3/FyersWebsocket/data_ws.py\", line 1517, in on_open\n    self.OnOpen()\nTypeError: onopen() missing 1 required positional argument: 'message'","exception_name":"TypeError"}
{"level":"ERROR","location":"[exception:108] fyers_logger","message":"onopen() missing 1 required positional argument: 'message'","timestamp":"2024-04-30 06:50:37,921+0000","service":"FyersDataSocket","exception":"Traceback (most recent call last):\n  File \"/usr/local/lib/python3.8/site-packages/fyers_apiv3/FyersWebsocket/data_ws.py\", line 1517, in on_open\n    self.OnOpen()\nTypeError: onopen() missing 1 required positional argument: 'message'","exception_name":"TypeError"}
{"level":"ERROR","location":"[exception:108] fyers_logger","message":"onopen() missing 1 required positional argument: 'message'","timestamp":"2024-04-30 06:52:31,200+0000","service":"FyersDataSocket","exception":"Traceback (most recent call last):\n  File \"/usr/local/lib/python3.8/site-packages/fyers_apiv3/FyersWebsocket/data_ws.py\", line 1517, in on_open\n    self.OnOpen()\nTypeError: onopen() missing 1 required positional argument: 'message'","exception_name":"TypeError"}
{"level":"ERROR","location":"[exception:108] fyers_logger","message":"onopen() missing 1 required positional argument: 'message'","timestamp":"2024-04-30 06:56:45,788+0000","service":"FyersDataSocket","exception":"Traceback (most recent call last):\n  File \"/usr/local/lib/python3.8/site-packages/fyers_apiv3/FyersWebsocket/data_ws.py\", line 1517, in on_open\n    self.OnOpen()\nTypeError: onopen() missing 1 required positional argument: 'message'","exception_name":"TypeError"}
{"level":"ERROR","location":"[exception:108] fyers_logger","message":"onopen() missing 1 required positional argument: 'message'","timestamp":"2024-04-30 07:21:38,246+0000","service":"FyersDataSocket","exception":"Traceback (most recent call last):\n  File \"/usr/local/lib/python3.8/site-packages/fyers_apiv3/FyersWebsocket/data_ws.py\", line 1517, in on_open\n    self.OnOpen()\nTypeError: onopen() missing 1 required positional argument: 'message'","exception_name":"TypeError"}
{"level":"ERROR","location":"[exception:108] fyers_logger","message":"onopen() missing 1 required positional argument: 'message'","timestamp":"2024-04-30 07:21:44,665+0000","service":"FyersDataSocket","exception":"Traceback (most recent call last):\n  File \"/usr/local/lib/python3.8/site-packages/fyers_apiv3/FyersWebsocket/data_ws.py\", line 1517, in on_open\n    self.OnOpen()\nTypeError: onopen() missing 1 required positional argument: 'message'","exception_name":"TypeError"}
{"level":"ERROR","location":"[exception:108] fyers_logger","message":"onopen() missing 1 required positional argument: 'message'","timestamp":"2024-04-30 07:21:47,460+0000","service":"FyersDataSocket","exception":"Traceback (most recent call last):\n  File \"/usr/local/lib/python3.8/site-packages/fyers_apiv3/FyersWebsocket/data_ws.py\", line 1517, in on_open\n    self.OnOpen()\nTypeError: onopen() missing 1 required positional argument: 'message'","exception_name":"TypeError"}
{"level":"ERROR","location":"[exception:108] fyers_logger","message":"onopen() missing 1 required positional argument: 'message'","timestamp":"2024-04-30 07:23:52,241+0000","service":"FyersDataSocket","exception":"Traceback (most recent call last):\n  File \"/usr/local/lib/python3.8/site-packages/fyers_apiv3/FyersWebsocket/data_ws.py\", line 1517, in on_open\n    self.OnOpen()\nTypeError: onopen() missing 1 required positional argument: 'message'","exception_name":"TypeError"}
{"level":"ERROR","location":"[exception:108] fyers_logger","message":"subscribe() missing 1 required positional argument: 'symbols'","timestamp":"2024-04-30 07:52:35,343+0000","service":"FyersDataSocket","exception":"Traceback (most recent call last):\n  File \"/usr/local/lib/python3.8/site-packages/fyers_apiv3/FyersWebsocket/data_ws.py\", line 1517, in on_open\n    self.OnOpen()\n  File \"/code/fyersapi/consumers.py\", line 190, in on_open\n    self.fyers.subscribe(data_type=data_type)\nTypeError: subscribe() missing 1 required positional argument: 'symbols'","exception_name":"TypeError"}
{"level":"ERROR","location":"[exception:108] fyers_logger","message":"subscribe() missing 1 required positional argument: 'symbols'","timestamp":"2024-04-30 07:52:52,678+0000","service":"FyersDataSocket","exception":"Traceback (most recent call last):\n  File \"/usr/local/lib/python3.8/site-packages/fyers_apiv3/FyersWebsocket/data_ws.py\", line 1517, in on_open\n    self.OnOpen()\n  File \"/code/fyersapi/consumers.py\", line 190, in on_open\n    self.fyers.subscribe(data_type=data_type)\nTypeError: subscribe() missing 1 required positional argument: 'symbols'","exception_name":"TypeError"}
{"level":"ERROR","location":"[exception:108] fyers_logger","message":"subscribe() missing 1 required positional argument: 'symbols'","timestamp":"2024-04-30 07:54:11,266+0000","service":"FyersDataSocket","exception":"Traceback (most recent call last):\n  File \"/usr/local/lib/python3.8/site-packages/fyers_apiv3/FyersWebsocket/data_ws.py\", line 1517, in on_open\n    self.OnOpen()\n  File \"/code/fyersapi/consumers.py\", line 190, in on_open\n    Callback function to subscribe to data type and symbols upon WebSocket connection.\nTypeError: subscribe() missing 1 required positional argument: 'symbols'","exception_name":"TypeError"}
{"level":"ERROR","location":"[exception:108] fyers_logger","message":"subscribe() missing 1 required positional argument: 'symbols'","timestamp":"2024-04-30 07:54:31,367+0000","service":"FyersDataSocket","exception":"Traceback (most recent call last):\n  File \"/usr/local/lib/python3.8/site-packages/fyers_apiv3/FyersWebsocket/data_ws.py\", line 1517, in on_open\n    self.OnOpen()\n  File \"/code/fyersapi/consumers.py\", line 190, in on_open\n    Callback function to subscribe to data type and symbols upon WebSocket connection.\nTypeError: subscribe() missing 1 required positional argument: 'symbols'","exception_name":"TypeError"}
{"level":"ERROR","location":"[exception:108] fyers_logger","message":"onopen() missing 1 required positional argument: 'message'","timestamp":"2024-04-30 08:43:21,409+0000","service":"FyersDataSocket","exception":"Traceback (most recent call last):\n  File \"/usr/local/lib/python3.8/site-packages/fyers_apiv3/FyersWebsocket/data_ws.py\", line 1517, in on_open\n    self.OnOpen()\nTypeError: onopen() missing 1 required positional argument: 'message'","exception_name":"TypeError"}
{"level":"ERROR","location":"[exception:108] fyers_logger","message":"onopen() missing 1 required positional argument: 'message'","timestamp":"2024-04-30 08:43:45,103+0000","service":"FyersDataSocket","exception":"Traceback (most recent call last):\n  File \"/usr/local/lib/python3.8/site-packages/fyers_apiv3/FyersWebsocket/data_ws.py\", line 1517, in on_open\n    self.OnOpen()\nTypeError: onopen() missing 1 required positional argument: 'message'","exception_name":"TypeError"}
{"level":"ERROR","location":"[exception:108] fyers_logger","message":"onopen() missing 1 required positional argument: 'message'","timestamp":"2024-04-30 08:43:51,995+0000","service":"FyersDataSocket","exception":"Traceback (most recent call last):\n  File \"/usr/local/lib/python3.8/site-packages/fyers_apiv3/FyersWebsocket/data_ws.py\", line 1517, in on_open\n    self.OnOpen()\nTypeError: onopen() missing 1 required positional argument: 'message'","exception_name":"TypeError"}
{"level":"ERROR","location":"[exception:108] fyers_logger","message":"onopen() missing 1 required positional argument: 'message'","timestamp":"2024-04-30 08:44:03,486+0000","service":"FyersDataSocket","exception":"Traceback (most recent call last):\n  File \"/usr/local/lib/python3.8/site-packages/fyers_apiv3/FyersWebsocket/data_ws.py\", line 1517, in on_open\n    self.OnOpen()\nTypeError: onopen() missing 1 required positional argument: 'message'","exception_name":"TypeError"}
{"level":"ERROR","location":"[exception:108] fyers_logger","message":"onopen() missing 1 required positional argument: 'message'","timestamp":"2024-04-30 08:45:58,911+0000","service":"FyersDataSocket","exception":"Traceback (most recent call last):\n  File \"/usr/local/lib/python3.8/site-packages/fyers_apiv3/FyersWebsocket/data_ws.py\", line 1517, in on_open\n    self.OnOpen()\nTypeError: onopen() missing 1 required positional argument: 'message'","exception_name":"TypeError"}
{"level":"ERROR","location":"[__on_message:248] order_ws","message":"Expecting value: line 1 column 1 (char 0)","timestamp":"2024-05-01 06:35:43,118+0000","service":"FyersDataSocket"}
{"level":"ERROR","location":"[exception:108] fyers_logger","message":"object of type 'NoneType' has no len()","timestamp":"2024-05-07 14:42:24,051+0000","service":"FyersDataSocket","exception":"Traceback (most recent call last):\n  File \"/usr/local/lib/python3.8/site-packages/fyers_apiv3/FyersWebsocket/data_ws.py\", line 308, in __access_token_msg\n    buffer_size = 18 + len(self.__hsm_token) + len(self.source)\nTypeError: object of type 'NoneType' has no len()","exception_name":"TypeError"}
{"level":"ERROR","location":"[exception:108] fyers_logger","message":"object of type 'NoneType' has no len()","timestamp":"2024-05-07 14:42:36,420+0000","service":"FyersDataSocket","exception":"Traceback (most recent call last):\n  File \"/usr/local/lib/python3.8/site-packages/fyers_apiv3/FyersWebsocket/data_ws.py\", line 308, in __access_token_msg\n    buffer_size = 18 + len(self.__hsm_token) + len(self.source)\nTypeError: object of type 'NoneType' has no len()","exception_name":"TypeError"}
{"level":"ERROR","location":"[exception:108] fyers_logger","message":"local variable 'first_expiry_ts' referenced before assignment","timestamp":"2024-05-07 19:18:39,992+0000","service":"FyersDataSocket","exception":"Traceback (most recent call last):\n  File \"/usr/local/lib/python3.8/site-packages/fyers_apiv3/FyersWebsocket/data_ws.py\", line 1517, in on_open\n    self.OnOpen()\n  File \"/code/fyersapi/consumers.py\", line 152, in on_open\n    getdata = self.getOptionStrikes()\n  File \"/code/fyersapi/consumers.py\", line 199, in getOptionStrikes\n    \"timestamp\": first_expiry_ts\nUnboundLocalError: local variable 'first_expiry_ts' referenced before assignment","exception_name":"UnboundLocalError"}
{"level":"ERROR","location":"[exception:108] fyers_logger","message":"local variable 'first_expiry_ts' referenced before assignment","timestamp":"2024-05-07 19:20:08,287+0000","service":"FyersDataSocket","exception":"Traceback (most recent call last):\n  File \"/usr/local/lib/python3.8/site-packages/fyers_apiv3/FyersWebsocket/data_ws.py\", line 1517, in on_open\n    self.OnOpen()\n  File \"/code/fyersapi/consumers.py\", line 152, in on_open\n    getdata = self.getOptionStrikes()\n  File \"/code/fyersapi/consumers.py\", line 195, in getOptionStrikes\n    if first_expiry_ts:\nUnboundLocalError: local variable 'first_expiry_ts' referenced before assignment","exception_name":"UnboundLocalError"}
{"level":"ERROR","location":"[exception:108] fyers_logger","message":"Attempt to send on a closed protocol","timestamp":"2024-05-08 04:58:12,356+0000","service":"FyersDataSocket","exception":"Traceback (most recent call last):\n  File \"/usr/local/lib/python3.8/site-packages/fyers_apiv3/FyersWebsocket/data_ws.py\", line 1434, in On_message\n    self.OnMessage(message)\n  File \"/code/fyersapi/consumers.py\", line 159, in on_message\n    self.send(text_data=f\"{message}\")\n  File \"/usr/local/lib/python3.8/site-packages/channels/generic/websocket.py\", line 74, in send\n    super().send({\"type\": \"websocket.send\", \"text\": text_data})\n  File \"/usr/local/lib/python3.8/site-packages/channels/consumer.py\", line 133, in send\n    self.base_send(message)\n  File \"/usr/local/lib/python3.8/site-packages/asgiref/sync.py\", line 277, in __call__\n    return call_result.result()\n  File \"/usr/local/lib/python3.8/concurrent/futures/_base.py\", line 437, in result\n    return self.__get_result()\n  File \"/usr/local/lib/python3.8/concurrent/futures/_base.py\", line 389, in __get_result\n    raise self._exception\n  File \"/usr/local/lib/python3.8/site-packages/asgiref/sync.py\", line 353, in main_wrap\n    result = await self.awaitable(*args, **kwargs)\n  File \"/usr/local/lib/python3.8/site-packages/channels/sessions.py\", line 226, in send\n    return await self.real_send(message)\n  File \"/usr/local/lib/python3.8/site-packages/daphne/server.py\", line 234, in handle_reply\n    protocol.handle_reply(message)\n  File \"/usr/local/lib/python3.8/site-packages/daphne/ws_protocol.py\", line 202, in handle_reply\n    self.serverSend(message[\"text\"], False)\n  File \"/usr/local/lib/python3.8/site-packages/daphne/ws_protocol.py\", line 256, in serverSend\n    self.sendMessage(content.encode(\"utf8\"), binary)\n  File \"/usr/local/lib/python3.8/site-packages/autobahn/websocket/protocol.py\", line 2275, in sendMessage\n    raise Disconnected(\"Attempt to send on a closed protocol\")\nautobahn.exception.Disconnected: Attempt to send on a closed protocol","exception_name":"Disconnected"}
{"level":"ERROR","location":"[exception:108] fyers_logger","message":"Attempt to send on a closed protocol","timestamp":"2024-05-08 06:06:07,118+0000","service":"FyersDataSocket","exception":"Traceback (most recent call last):\n  File \"/usr/local/lib/python3.8/site-packages/fyers_apiv3/FyersWebsocket/data_ws.py\", line 1434, in On_message\n    self.OnMessage(message)\n  File \"/code/fyersapi/consumers.py\", line 169, in on_message\n    self.send(text_data=f\"{message}\")\n  File \"/usr/local/lib/python3.8/site-packages/channels/generic/websocket.py\", line 74, in send\n    super().send({\"type\": \"websocket.send\", \"text\": text_data})\n  File \"/usr/local/lib/python3.8/site-packages/channels/consumer.py\", line 133, in send\n    self.base_send(message)\n  File \"/usr/local/lib/python3.8/site-packages/asgiref/sync.py\", line 277, in __call__\n    return call_result.result()\n  File \"/usr/local/lib/python3.8/concurrent/futures/_base.py\", line 437, in result\n    return self.__get_result()\n  File \"/usr/local/lib/python3.8/concurrent/futures/_base.py\", line 389, in __get_result\n    raise self._exception\n  File \"/usr/local/lib/python3.8/site-packages/asgiref/sync.py\", line 353, in main_wrap\n    result = await self.awaitable(*args, **kwargs)\n  File \"/usr/local/lib/python3.8/site-packages/channels/sessions.py\", line 226, in send\n    return await self.real_send(message)\n  File \"/usr/local/lib/python3.8/site-packages/daphne/server.py\", line 234, in handle_reply\n    protocol.handle_reply(message)\n  File \"/usr/local/lib/python3.8/site-packages/daphne/ws_protocol.py\", line 202, in handle_reply\n    self.serverSend(message[\"text\"], False)\n  File \"/usr/local/lib/python3.8/site-packages/daphne/ws_protocol.py\", line 256, in serverSend\n    self.sendMessage(content.encode(\"utf8\"), binary)\n  File \"/usr/local/lib/python3.8/site-packages/autobahn/websocket/protocol.py\", line 2275, in sendMessage\n    raise Disconnected(\"Attempt to send on a closed protocol\")\nautobahn.exception.Disconnected: Attempt to send on a closed protocol","exception_name":"Disconnected"}
